Workbook

Sheet Financials>

Sheet HistoricalFS
B2: ="Historical Financial Statement - "&'Data Sheet'!B1 -> Historical Financial Statement - MARUTI SUZUKI INDIA LTD
B3: Years | C3: ='Data Sheet'!B16 -> 42460 | D3: ='Data Sheet'!C16 -> 42825 | E3: ='Data Sheet'!D16 -> 43190 | F3: ='Data Sheet'!E16 -> 43555 | G3: ='Data Sheet'!F16 -> 43921 | H3: ='Data Sheet'!G16 -> 44286 | I3: ='Data Sheet'!H16 -> 44651 | J3: ='Data Sheet'!I16 -> 45016 | ... L3: ='Data Sheet'!K16 -> 45747 | M3: LTM
B4: All Figures in Crores (₹)
A5: # | B5: Income Statement
B6: Sales | C6: =IFERROR('Data Sheet'!B17,0) -> 57589 | D6: =IFERROR('Data Sheet'!C17,0) -> 68085 | E6: =IFERROR('Data Sheet'!D17,0) -> 79809.4 | F6: =IFERROR('Data Sheet'!E17,0) -> 86068.5 | G6: =IFERROR('Data Sheet'!F17,0) -> 75660 | H6: =IFERROR('Data Sheet'!G17,0) -> 70372 | I6: =IFERROR('Data Sheet'!H17,0) -> 88329.8 | J6: =IFERROR('Data Sheet'!I17,0) -> 117571.3 | ... L6: =IFERROR('Data Sheet'!K17,0) -> 152913 | M6: =IFERROR(SUM('Data Sheet'!B42:K42),0) -> 393089.9
B7: Sales Growth | C7: - | D7: =D6/C6-1 -> 0.18225703 | E7: =E6/D6-1 -> 0.17220239 | F7: =F6/E6-1 -> 0.078425599 | G7: =G6/F6-1 -> -0.12093275 | H7: =H6/G6-1 -> -0.06989162 | I7: =I6/H6-1 -> 0.25518388 | J7: =J6/I6-1 -> 0.33104909 | K7: =K6/J6-1 -> 0.20657167 | ... M7: =M6/L6-1 -> 1.5706768
B9: COGS | C9: =IFERROR(SUM('Data Sheet'!B18,'Data Sheet'!B20:B22),0) -> 41823.4 | D9: =IFERROR(SUM('Data Sheet'!C18,'Data Sheet'!C20:C22),0) -> 50383.3 | E9: =IFERROR(SUM('Data Sheet'!D18,'Data Sheet'!D20:D22),0) -> 58944.2 | F9: =IFERROR(SUM('Data Sheet'!E18,'Data Sheet'!E20:E22),0) -> 63970.6 | G9: =IFERROR(SUM('Data Sheet'!F18,'Data Sheet'!F20:F22),0) -> 57895.8 | H9: =IFERROR(SUM('Data Sheet'!G18,'Data Sheet'!G20:G22),0) -> 55142 | I9: =IFERROR(SUM('Data Sheet'!H18,'Data Sheet'!H20:H22),0) -> 71671.9 | J9: =IFERROR(SUM('Data Sheet'!I18,'Data Sheet'!I20:I22),0) -> 93200 | ... L9: =IFERROR(SUM('Data Sheet'!K18,'Data Sheet'!K20:K22),0) -> 118791.3 | M9: =IFERROR(SUM('Data Sheet'!B43:K43),0) -> 342809.7
B10: COGS % Sales | C10: =C9/C6 -> 0.72623939 | D10: =D9/D6 -> 0.74000588 | E10: =E9/E6 -> 0.73856212 | F10: =F9/F6 -> 0.74325218 | G10: =G9/G6 -> 0.76521015 | H10: =H9/H6 -> 0.7835787 | I10: =I9/I6 -> 0.81141246 | J10: =J9/J6 -> 0.79271047 | ... M10: =M9/M6 -> 0.87208982
B12: Gross Profit | C12: =C6-C9 -> 15765.6 | D12: =D6-D9 -> 17701.7 | E12: =E6-E9 -> 20865.2 | F12: =F6-F9 -> 22097.9 | G12: =G6-G9 -> 17764.2 | H12: =H6-H9 -> 15230 | I12: =I6-I9 -> 16657.9 | J12: =J6-J9 -> 24371.3 | ... M12: =M6-M9 -> 50280.2
B13: Gross Margins | C13: =C12/C6 -> 0.27376061 | D13: =D12/D6 -> 0.25999412 | E13: =E12/E6 -> 0.26143788 | F13: =F12/F6 -> 0.25674782 | G13: =G12/G6 -> 0.23478985 | H13: =H12/H6 -> 0.2164213 | I13: =I12/I6 -> 0.18858754 | J13: =J12/J6 -> 0.20728953 | ... M13: =M12/M6 -> 0.12791018
B15: Selling & General Expenses | C15: =IFERROR(SUM('Data Sheet'!B23:B24),0) -> 6736.7 | D15: =IFERROR(SUM('Data Sheet'!C23:C24),0) -> 7659.7 | E15: =IFERROR(SUM('Data Sheet'!D23:D24),0) -> 8706.5 | F15: =IFERROR(SUM('Data Sheet'!E23:E24),0) -> 10830 | G15: =IFERROR(SUM('Data Sheet'!F23:F24),0) -> 10647.9 | H15: =IFERROR(SUM('Data Sheet'!G23:G24),0) -> 9545.8 | I15: =IFERROR(SUM('Data Sheet'!H23:H24),0) -> 10999 | J15: =IFERROR(SUM('Data Sheet'!I23:I24),0) -> 13746 | ... L15: =IFERROR(SUM('Data Sheet'!K23:K24),0) -> 15125.6
B16: S&G Exp % Sales | C16: =C15/C6 -> 0.11697894 | D16: =D15/D6 -> 0.11250202 | E16: =E15/E6 -> 0.10909116 | F16: =F15/F6 -> 0.12583001 | G16: =G15/G6 -> 0.14073354 | H16: =H15/H6 -> 0.1356477 | I16: =I15/I6 -> 0.12452196 | J16: =J15/J6 -> 0.11691629 | ... L16: =L15/L6 -> 0.098916377
B18: EBITDA | C18: =C12-C15 -> 9028.9 | D18: =D12-D15 -> 10042 | E18: =E12-E15 -> 12158.7 | F18: =F12-F15 -> 11267.9 | G18: =G12-G15 -> 7116.3 | H18: =H12-H15 -> 5684.2 | I18: =I12-I15 -> 5658.9 | J18: =J12-J15 -> 10625.3 | ... M18: =M12-M15 -> 50280.2
B19: EBITDA Margins | C19: =C18/C6 -> 0.15678168 | D19: =D18/D6 -> 0.14749211 | E19: =E18/E6 -> 0.15234672 | F19: =F18/F6 -> 0.13091782 | G19: =G18/G6 -> 0.094056305 | H19: =H18/H6 -> 0.080773603 | I19: =I18/I6 -> 0.064065581 | J19: =J18/J6 -> 0.090373246 | ... M19: =M18/M6 -> 0.12791018
B21: Interest | C21: =IFERROR('Data Sheet'!B46,0) -> 35.1 | D21: =IFERROR('Data Sheet'!C46,0) -> 35.8 | E21: =IFERROR('Data Sheet'!D46,0) -> 76.2 | F21: =IFERROR('Data Sheet'!E46,0) -> 57.3 | G21: =IFERROR('Data Sheet'!F46,0) -> 43 | H21: =IFERROR('Data Sheet'!G46,0) -> 46.3 | I21: =IFERROR('Data Sheet'!H46,0) -> 47.6 | J21: =IFERROR('Data Sheet'!I46,0) -> 46.8 | ... L21: =IFERROR('Data Sheet'!K46,0) -> 61.7 | M21: =IFERROR(SUM('Data Sheet'!B46:K46),0) -> 507
B22: Interest % Sales | C22: =C21/C6 -> 0.0006094914 | D22: =D21/D6 -> 0.00052581332 | E22: =E21/E6 -> 0.00095477475 | F22: =F21/F6 -> 0.00066574879 | G22: =G21/G6 -> 0.00056833201 | H22: =H21/H6 -> 0.00065793213 | I22: =I21/I6 -> 0.00053888948 | J22: =J21/J6 -> 0.00039805633 | ... M22: =M21/M6 -> 0.0012897813
B24: Depreciation | C24: =IFERROR('Data Sheet'!B26,0) -> 2821.8 | D24: =IFERROR('Data Sheet'!C26,0) -> 2603.9 | E24: =IFERROR('Data Sheet'!D26,0) -> 2759.8 | F24: =IFERROR('Data Sheet'!E26,0) -> 3020.8 | G24: =IFERROR('Data Sheet'!F26,0) -> 3528.4 | H24: =IFERROR('Data Sheet'!G26,0) -> 3034.1 | I24: =IFERROR('Data Sheet'!H26,0) -> 2789 | J24: =IFERROR('Data Sheet'!I26,0) -> 2825.7 | ... L24: =IFERROR('Data Sheet'!K26,0) -> 5608.2 | M24: =IFERROR(SUM('Data Sheet'!B45:K45),0) -> 14543.5
B25: Depreciation % Sales | C25: =C24/C6 -> 0.048998941 | D25: =D24/D6 -> 0.038244841 | E25: =E24/E6 -> 0.034579887 | F25: =F24/F6 -> 0.035097626 | G25: =G24/G6 -> 0.046634946 | H25: =H24/H6 -> 0.043115159 | I25: =I24/I6 -> 0.031574848 | J25: =J24/J6 -> 0.024033927 | ... M25: =M24/M6 -> 0.036997898
B27: Earnings Before Tax | C27: =C18-SUM(C21,C24) -> 6172 | D27: =D18-SUM(D21,D24) -> 7402.3 | E27: =E18-SUM(E21,E24) -> 9322.7 | F27: =F18-SUM(F21,F24) -> 8189.8 | G27: =G18-SUM(G21,G24) -> 3544.9 | H27: =H18-SUM(H21,H24) -> 2603.8 | I27: =I18-SUM(I21,I24) -> 2822.3 | J27: =J18-SUM(J21,J24) -> 7752.8 | ... M27: =M18-SUM(M21,M24) -> 35229.7
B28: EBT % Sales | C28: =C27/C6 -> 0.10717324 | D28: =D27/D6 -> 0.10872145 | E28: =E27/E6 -> 0.11681205 | F28: =F27/F6 -> 0.095154441 | G28: =G27/G6 -> 0.046853027 | H28: =H27/H6 -> 0.037000512 | I28: =I27/I6 -> 0.031951844 | J28: =J27/J6 -> 0.065941263 | ... M28: =M27/M6 -> 0.089622501
B30: Tax | C30: =IFERROR('Data Sheet'!B29,0) -> 2087.5 | D30: =IFERROR('Data Sheet'!C29,0) -> 2616.2 | E30: =IFERROR('Data Sheet'!D29,0) -> 3286.2 | F30: =IFERROR('Data Sheet'!E29,0) -> 2973.2 | G30: =IFERROR('Data Sheet'!F29,0) -> 1425.2 | H30: =IFERROR('Data Sheet'!G29,0) -> 931.9 | I30: =IFERROR('Data Sheet'!H29,0) -> 817.7 | J30: =IFERROR('Data Sheet'!I29,0) -> 2112.1 | ... L30: =IFERROR('Data Sheet'!K29,0) -> 5119.8 | M30: =IFERROR(SUM('Data Sheet'!B48:K48),0) -> 11509.6
B31: Effective Tax Rate | C31: =C30/C27 -> 0.338221 | D31: =D30/D27 -> 0.35343069 | E31: =E30/E27 -> 0.35249445 | F31: =F30/F27 -> 0.36303695 | G31: =G30/G27 -> 0.40204237 | H31: =H30/H27 -> 0.35789999 | I31: =I30/I27 -> 0.28972824 | J31: =J30/J27 -> 0.27243061 | ... M31: =M30/M27 -> 0.32670162
B33: Net Profit | C33: =C27-C30 -> 4084.5 | D33: =D27-D30 -> 4786.1 | E33: =E27-E30 -> 6036.5 | F33: =F27-F30 -> 5216.6 | G33: =G27-G30 -> 2119.7 | H33: =H27-H30 -> 1671.9 | I33: =I27-I30 -> 2004.6 | J33: =J27-J30 -> 5640.7 | ... M33: =M27-M30 -> 23720.1
B34: Net Margins | C34: =C33/C6 -> 0.070925003 | D34: =D33/D6 -> 0.070295954 | E34: =E33/E6 -> 0.075636454 | F34: =F33/F6 -> 0.060609863 | G34: =G33/G6 -> 0.028016125 | H34: =H33/H6 -> 0.023758029 | I34: =I33/I6 -> 0.022694493 | J34: =J33/J6 -> 0.047976845 | ... M34: =M33/M6 -> 0.060342685
B36: No of Equity Shares | C36: =IFERROR('Data Sheet'!B93,0) -> 30.21 | D36: =IFERROR('Data Sheet'!C93,0) -> 30.21 | E36: =IFERROR('Data Sheet'!D93,0) -> 30.21 | F36: =IFERROR('Data Sheet'!E93,0) -> 30.21 | G36: =IFERROR('Data Sheet'!F93,0) -> 30.21 | H36: =IFERROR('Data Sheet'!G93,0) -> 30.21 | I36: =IFERROR('Data Sheet'!H93,0) -> 30.21 | J36: =IFERROR('Data Sheet'!I93,0) -> 30.21 | ... L36: =IFERROR('Data Sheet'!K93,0) -> 31.44 | M36: =L36 -> 31.44
B38: Earnings per Share | C38: =C33/C36 -> 135.20357 | D38: =D33/D36 -> 158.42767 | E38: =E33/E36 -> 199.81794 | F38: =F33/F36 -> 172.67792 | G38: =G33/G36 -> 70.165508 | H38: =H33/H36 -> 55.342602 | I38: =I33/I36 -> 66.355511 | J38: =J33/J36 -> 186.71632 | ... M38: =M33/M36 -> 754.45611
B39: EPS Growth % | C39: - | D39: =D38/C38-1 -> 0.17177133 | E39: =E38/D38-1 -> 0.26125656 | F39: =F38/E38-1 -> -0.13582374 | G39: =G38/F38-1 -> -0.59366254 | H39: =H38/G38-1 -> -0.21125631 | I39: =I38/H38-1 -> 0.19899516 | J39: =J38/I38-1 -> 1.8138781 | K39: =K38/J38-1 -> 0.5328529 | ... M39: =M38/L38-1 -> 1.8904392
B41: Dividend per Share | C41: =IFERROR(SUM('Data Sheet'!B31/HistoricalFS!C36),0) -> 34.988414 | D41: =IFERROR(SUM('Data Sheet'!C31/HistoricalFS!D36),0) -> 74.975174 | E41: =IFERROR(SUM('Data Sheet'!D31/HistoricalFS!E36),0) -> 79.973519 | F41: =IFERROR(SUM('Data Sheet'!E31/HistoricalFS!F36),0) -> 79.973519 | G41: =IFERROR(SUM('Data Sheet'!F31/HistoricalFS!G36),0) -> 59.980139 | H41: =IFERROR(SUM('Data Sheet'!G31/HistoricalFS!H36),0) -> 44.985104 | I41: =IFERROR(SUM('Data Sheet'!H31/HistoricalFS!I36),0) -> 59.980139 | J41: =IFERROR(SUM('Data Sheet'!I31/HistoricalFS!J36),0) -> 89.970209 | ... M41: =IFERROR(SUM('Data Sheet'!L31/HistoricalFS!M36),0) -> 0
B42: Dividend payout ratio | C42: =IFERROR(C41/C38,0) -> 0.2587832 | D42: =IFERROR(D41/D38,0) -> 0.47324544 | E42: =IFERROR(E41/E38,0) -> 0.40023192 | F42: =IFERROR(F41/F38,0) -> 0.46313691 | G42: =IFERROR(G41/G38,0) -> 0.85483795 | H42: =IFERROR(H41/H38,0) -> 0.81284766 | I42: =IFERROR(I41/I38,0) -> 0.90392098 | J42: =IFERROR(J41/J38,0) -> 0.48185509 | ... M42: =IFERROR(M41/M38,0) -> 0
B44: Retained Earnings | C44: =IFERROR(IF(C38>C41,1-C42,0),0) -> 0.7412168 | D44: =IFERROR(IF(D38>D41,1-D42,0),0) -> 0.52675456 | E44: =IFERROR(IF(E38>E41,1-E42,0),0) -> 0.59976808 | F44: =IFERROR(IF(F38>F41,1-F42,0),0) -> 0.53686309 | G44: =IFERROR(IF(G38>G41,1-G42,0),0) -> 0.14516205 | H44: =IFERROR(IF(H38>H41,1-H42,0),0) -> 0.18715234 | I44: =IFERROR(IF(I38>I41,1-I42,0),0) -> 0.096079018 | J44: =IFERROR(IF(J38>J41,1-J42,0),0) -> 0.51814491 | ... M44: =IFERROR(IF(M38>M41,1-M42,0),0) -> 1
A46: # | B46: Balance Sheet
B47: Equity Share Capital | C47: =IFERROR('Data Sheet'!B57,0) -> 151 | D47: =IFERROR('Data Sheet'!C57,0) -> 151 | E47: =IFERROR('Data Sheet'!D57,0) -> 151 | F47: =IFERROR('Data Sheet'!E57,0) -> 151 | G47: =IFERROR('Data Sheet'!F57,0) -> 151 | H47: =IFERROR('Data Sheet'!G57,0) -> 151 | I47: =IFERROR('Data Sheet'!H57,0) -> 151 | J47: =IFERROR('Data Sheet'!I57,0) -> 151 | ... L47: =IFERROR('Data Sheet'!K57,0) -> 157.2
B48: Reserves | C48: =IFERROR('Data Sheet'!B58,0) -> 30465 | D48: =IFERROR('Data Sheet'!C58,0) -> 36924.1 | E48: =IFERROR('Data Sheet'!D58,0) -> 42408.4 | F48: =IFERROR('Data Sheet'!E58,0) -> 46941.1 | G48: =IFERROR('Data Sheet'!F58,0) -> 49262 | H48: =IFERROR('Data Sheet'!G58,0) -> 52349.6 | I48: =IFERROR('Data Sheet'!H58,0) -> 55182.5 | J48: =IFERROR('Data Sheet'!I58,0) -> 61640.3 | ... L48: =IFERROR('Data Sheet'!K58,0) -> 96082.7
B49: Borrowings | C49: =IFERROR('Data Sheet'!B59,0) -> 230.9 | D49: =IFERROR('Data Sheet'!C59,0) -> 483.6 | E49: =IFERROR('Data Sheet'!D59,0) -> 120.8 | F49: =IFERROR('Data Sheet'!E59,0) -> 159.6 | G49: =IFERROR('Data Sheet'!F59,0) -> 184.1 | H49: =IFERROR('Data Sheet'!G59,0) -> 540.9 | I49: =IFERROR('Data Sheet'!H59,0) -> 425.5 | J49: =IFERROR('Data Sheet'!I59,0) -> 1247.3 | ... L49: =IFERROR('Data Sheet'!K59,0) -> 87
B50: Other Liabilities | C50: =IFERROR('Data Sheet'!B60,0) -> 11878.6 | D50: =IFERROR('Data Sheet'!C60,0) -> 14401.8 | E50: =IFERROR('Data Sheet'!D60,0) -> 17568.2 | F50: =IFERROR('Data Sheet'!E60,0) -> 16717 | G50: =IFERROR('Data Sheet'!F60,0) -> 14030.6 | H50: =IFERROR('Data Sheet'!G60,0) -> 18334.6 | I50: =IFERROR('Data Sheet'!H60,0) -> 18896.5 | J50: =IFERROR('Data Sheet'!I60,0) -> 21558.3 | ... L50: =IFERROR('Data Sheet'!K60,0) -> 35644.3
B51: Total Liabilities | C51: =IFERROR('Data Sheet'!B61,0) -> 42725.5 | D51: =IFERROR('Data Sheet'!C61,0) -> 51960.5 | E51: =IFERROR('Data Sheet'!D61,0) -> 60248.4 | F51: =IFERROR('Data Sheet'!E61,0) -> 63968.7 | G51: =IFERROR('Data Sheet'!F61,0) -> 63627.7 | H51: =IFERROR('Data Sheet'!G61,0) -> 71376.1 | I51: =IFERROR('Data Sheet'!H61,0) -> 74655.5 | J51: =IFERROR('Data Sheet'!I61,0) -> 84596.9 | ... L51: =IFERROR('Data Sheet'!K61,0) -> 131971.2
B53: Fixed Assets Net Block | C53: =IFERROR('Data Sheet'!B62,0) -> 12529.6 | D53: =IFERROR('Data Sheet'!C62,0) -> 13310.7 | E53: =IFERROR('Data Sheet'!D62,0) -> 13388.8 | F53: =IFERROR('Data Sheet'!E62,0) -> 15437.3 | G53: =IFERROR('Data Sheet'!F62,0) -> 15744.4 | H53: =IFERROR('Data Sheet'!G62,0) -> 14988.7 | I53: =IFERROR('Data Sheet'!H62,0) -> 13747.2 | J53: =IFERROR('Data Sheet'!I62,0) -> 17830.4 | ... L53: =IFERROR('Data Sheet'!K62,0) -> 32982.7
B54: Capital Work in Progress | C54: =IFERROR('Data Sheet'!B63,0) -> 1006.9 | D54: =IFERROR('Data Sheet'!C63,0) -> 1252.3 | E54: =IFERROR('Data Sheet'!D63,0) -> 2132.1 | F54: =IFERROR('Data Sheet'!E63,0) -> 1606.9 | G54: =IFERROR('Data Sheet'!F63,0) -> 1415.2 | H54: =IFERROR('Data Sheet'!G63,0) -> 1496.8 | I54: =IFERROR('Data Sheet'!H63,0) -> 2936.5 | J54: =IFERROR('Data Sheet'!I63,0) -> 2904.1 | ... L54: =IFERROR('Data Sheet'!K63,0) -> 7929
B55: Investments | C55: =IFERROR('Data Sheet'!B64,0) -> 20675.8 | D55: =IFERROR('Data Sheet'!C64,0) -> 29150.6 | E55: =IFERROR('Data Sheet'!D64,0) -> 36123.1 | F55: =IFERROR('Data Sheet'!E64,0) -> 37503.6 | G55: =IFERROR('Data Sheet'!F64,0) -> 37488 | H55: =IFERROR('Data Sheet'!G64,0) -> 42944.8 | I55: =IFERROR('Data Sheet'!H64,0) -> 42034.7 | J55: =IFERROR('Data Sheet'!I64,0) -> 49184.3 | ... L55: =IFERROR('Data Sheet'!K64,0) -> 66265.4
B56: Other Assets | C56: =IFERROR('Data Sheet'!B65-SUM('Data Sheet'!B67:B69),0) -> 4006.5 | D56: =IFERROR('Data Sheet'!C65-SUM('Data Sheet'!C67:C69),0) -> 3757.1 | E56: =IFERROR('Data Sheet'!D65-SUM('Data Sheet'!D67:D69),0) -> 3904.8 | F56: =IFERROR('Data Sheet'!E65-SUM('Data Sheet'!E67:E69),0) -> 3597.7 | G56: =IFERROR('Data Sheet'!F65-SUM('Data Sheet'!F67:F69),0) -> 3759.5 | H56: =IFERROR('Data Sheet'!G65-SUM('Data Sheet'!G67:G69),0) -> 4569.8 | I56: =IFERROR('Data Sheet'!H65-SUM('Data Sheet'!H67:H69),0) -> 7328.1 | J56: =IFERROR('Data Sheet'!I65-SUM('Data Sheet'!I67:I69),0) -> 7051.6 | ... L56: =IFERROR('Data Sheet'!K65-SUM('Data Sheet'!K67:K69),0) -> 10788.3
...

Sheet Ratio Analysis
B2: ="Ratio Analysis - "&'Data Sheet'!B1 -> Ratio Analysis - MARUTI SUZUKI INDIA LTD
B3: Years | C3: ='Data Sheet'!B16 -> 42460 | D3: ='Data Sheet'!C16 -> 42825 | E3: ='Data Sheet'!D16 -> 43190 | F3: ='Data Sheet'!E16 -> 43555 | G3: ='Data Sheet'!F16 -> 43921 | H3: ='Data Sheet'!G16 -> 44286 | I3: ='Data Sheet'!H16 -> 44651 | J3: ='Data Sheet'!I16 -> 45016 | ... L3: ='Data Sheet'!K16 -> 45747 | M3: Trend | N3: Mean | O3: Median
B5: SalesGrowth | D5: =IFERROR(HistoricalFS!D7,0) -> 0.18225703 | E5: =IFERROR(HistoricalFS!E7,0) -> 0.17220239 | F5: =IFERROR(HistoricalFS!F7,0) -> 0.078425599 | G5: =IFERROR(HistoricalFS!G7,0) -> -0.12093275 | H5: =IFERROR(HistoricalFS!H7,0) -> -0.06989162 | I5: =IFERROR(HistoricalFS!I7,0) -> 0.25518388 | J5: =IFERROR(HistoricalFS!J7,0) -> 0.33104909 | K5: =IFERROR(HistoricalFS!K7,0) -> 0.20657167 | L5: =IFERROR(HistoricalFS!L7,0) -> 0.077928523 | N5: =IFERROR(AVERAGE(D5:L5),0) -> 0.12364376 | O5: =IFERROR(MEDIAN(D5:L5),0) -> 0.17220239
B6: GrossMargin | D6: =IFERROR(HistoricalFS!D13,0) -> 0.25999412 | E6: =IFERROR(HistoricalFS!E13,0) -> 0.26143788 | F6: =IFERROR(HistoricalFS!F13,0) -> 0.25674782 | G6: =IFERROR(HistoricalFS!G13,0) -> 0.23478985 | H6: =IFERROR(HistoricalFS!H13,0) -> 0.2164213 | I6: =IFERROR(HistoricalFS!I13,0) -> 0.18858754 | J6: =IFERROR(HistoricalFS!J13,0) -> 0.20728953 | K6: =IFERROR(HistoricalFS!K13,0) -> 0.23590036 | L6: =IFERROR(HistoricalFS!L13,0) -> 0.22314453 | N6: =IFERROR(AVERAGE(D6:L6),0) -> 0.23159033 | O6: =IFERROR(MEDIAN(D6:L6),0) -> 0.23478985
B7: EBITDA Growth | D7: =IFERROR(HistoricalFS!D18/HistoricalFS!C18-1,0) -> 0.11220636 | E7: =IFERROR(HistoricalFS!E18/HistoricalFS!D18-1,0) -> 0.2107847 | F7: =IFERROR(HistoricalFS!F18/HistoricalFS!E18-1,0) -> -0.073264411 | G7: =IFERROR(HistoricalFS!G18/HistoricalFS!F18-1,0) -> -0.36844487 | H7: =IFERROR(HistoricalFS!H18/HistoricalFS!G18-1,0) -> -0.20124222 | I7: =IFERROR(HistoricalFS!I18/HistoricalFS!H18-1,0) -> -0.0044509342 | J7: =IFERROR(HistoricalFS!J18/HistoricalFS!I18-1,0) -> 0.87762639 | K7: =IFERROR(HistoricalFS!K18/HistoricalFS!J18-1,0) -> 0.7173821 | L7: =IFERROR(HistoricalFS!L18/HistoricalFS!K18-1,0) -> 0.041013388 | N7: =IFERROR(AVERAGE(D7:L7),0) -> 0.1457345 | O7: =IFERROR(MEDIAN(D7:L7),0) -> 0.041013388
B8: EBIT Growth | D8: =IFERROR((HistoricalFS!D18-HistoricalFS!D24)/(HistoricalFS!C18-HistoricalFS!C24)-1,0) -> 0.19832128 | E8: =IFERROR((HistoricalFS!E18-HistoricalFS!E24)/(HistoricalFS!D18-HistoricalFS!D24)-1,0) -> 0.26361571 | F8: =IFERROR((HistoricalFS!F18-HistoricalFS!F24)/(HistoricalFS!E18-HistoricalFS!E24)-1,0) -> -0.12254626 | G8: =IFERROR((HistoricalFS!G18-HistoricalFS!G24)/(HistoricalFS!F18-HistoricalFS!F24)-1,0) -> -0.5649501 | H8: =IFERROR((HistoricalFS!H18-HistoricalFS!H24)/(HistoricalFS!G18-HistoricalFS!G24)-1,0) -> -0.26137852 | I8: =IFERROR((HistoricalFS!I18-HistoricalFS!I24)/(HistoricalFS!H18-HistoricalFS!H24)-1,0) -> 0.082940266 | J8: =IFERROR((HistoricalFS!J18-HistoricalFS!J24)/(HistoricalFS!I18-HistoricalFS!I24)-1,0) -> 1.7177254 | K8: =IFERROR((HistoricalFS!K18-HistoricalFS!K24)/(HistoricalFS!J18-HistoricalFS!J24)-1,0) -> 0.66571363 | L8: =IFERROR((HistoricalFS!L18-HistoricalFS!L24)/(HistoricalFS!K18-HistoricalFS!K24)-1,0) -> 0.03048053 | N8: =IFERROR(AVERAGE(D8:L8),0) -> 0.22332465 | O8: =IFERROR(MEDIAN(D8:L8),0) -> 0.082940266
B9: Net Profit Growth | D9: =IFERROR(HistoricalFS!D33/HistoricalFS!C33-1,0) -> 0.17177133 | E9: =IFERROR(HistoricalFS!E33/HistoricalFS!D33-1,0) -> 0.26125656 | F9: =IFERROR(HistoricalFS!F33/HistoricalFS!E33-1,0) -> -0.13582374 | G9: =IFERROR(HistoricalFS!G33/HistoricalFS!F33-1,0) -> -0.59366254 | H9: =IFERROR(HistoricalFS!H33/HistoricalFS!G33-1,0) -> -0.21125631 | I9: =IFERROR(HistoricalFS!I33/HistoricalFS!H33-1,0) -> 0.19899516 | J9: =IFERROR(HistoricalFS!J33/HistoricalFS!I33-1,0) -> 1.8138781 | K9: =IFERROR(HistoricalFS!K33/HistoricalFS!J33-1,0) -> 0.595263 | L9: =IFERROR(HistoricalFS!L33/HistoricalFS!K33-1,0) -> -0.088015647 | N9: =IFERROR(AVERAGE(D9:L9),0) -> 0.22360065 | O9: =IFERROR(MEDIAN(D9:L9),0) -> 0.17177133
B10: Dividend Growth | D10: =IFERROR(HistoricalFS!D41/HistoricalFS!C41-1,0) -> 1.1428571 | E10: =IFERROR(HistoricalFS!E41/HistoricalFS!D41-1,0) -> 0.066666667 | F10: =IFERROR(HistoricalFS!F41/HistoricalFS!E41-1,0) -> 0 | G10: =IFERROR(HistoricalFS!G41/HistoricalFS!F41-1,0) -> -0.25 | H10: =IFERROR(HistoricalFS!H41/HistoricalFS!G41-1,0) -> -0.25 | I10: =IFERROR(HistoricalFS!I41/HistoricalFS!H41-1,0) -> 0.33333333 | J10: =IFERROR(HistoricalFS!J41/HistoricalFS!I41-1,0) -> 0.5 | K10: =IFERROR(HistoricalFS!K41/HistoricalFS!J41-1,0) -> 0.38934879 | L10: =IFERROR(HistoricalFS!L41/HistoricalFS!K41-1,0) -> 0.08 | N10: =IFERROR(AVERAGE(D10:L10),0) -> 0.22357844 | O10: =IFERROR(MEDIAN(D10:L10),0) -> 0.08
B12: Gross Margin | C12: =IFERROR(HistoricalFS!C13,0) -> 0.27376061 | D12: =IFERROR(HistoricalFS!D13,0) -> 0.25999412 | E12: =IFERROR(HistoricalFS!E13,0) -> 0.26143788 | F12: =IFERROR(HistoricalFS!F13,0) -> 0.25674782 | G12: =IFERROR(HistoricalFS!G13,0) -> 0.23478985 | H12: =IFERROR(HistoricalFS!H13,0) -> 0.2164213 | I12: =IFERROR(HistoricalFS!I13,0) -> 0.18858754 | J12: =IFERROR(HistoricalFS!J13,0) -> 0.20728953 | ... L12: =IFERROR(HistoricalFS!L13,0) -> 0.22314453 | N12: =IFERROR(AVERAGE(D12:L12),0) -> 0.23159033 | O12: =IFERROR(MEDIAN(D12:L12),0) -> 0.23478985
B13: EBITDA Margin | C13: =IFERROR(HistoricalFS!C19,0) -> 0.15678168 | D13: =IFERROR(HistoricalFS!D19,0) -> 0.14749211 | E13: =IFERROR(HistoricalFS!E19,0) -> 0.15234672 | F13: =IFERROR(HistoricalFS!F19,0) -> 0.13091782 | G13: =IFERROR(HistoricalFS!G19,0) -> 0.094056305 | H13: =IFERROR(HistoricalFS!H19,0) -> 0.080773603 | I13: =IFERROR(HistoricalFS!I19,0) -> 0.064065581 | J13: =IFERROR(HistoricalFS!J19,0) -> 0.090373246 | ... L13: =IFERROR(HistoricalFS!L19,0) -> 0.12422816 | N13: =IFERROR(AVERAGE(D13:L13),0) -> 0.11254299 | O13: =IFERROR(MEDIAN(D13:L13),0) -> 0.12422816
B14: EBIT Margin | C14: =IFERROR((HistoricalFS!C18-HistoricalFS!C24)/HistoricalFS!C6,0) -> 0.10778274 | D14: =IFERROR((HistoricalFS!D18-HistoricalFS!D24)/HistoricalFS!D6,0) -> 0.10924726 | E14: =IFERROR((HistoricalFS!E18-HistoricalFS!E24)/HistoricalFS!E6,0) -> 0.11776683 | F14: =IFERROR((HistoricalFS!F18-HistoricalFS!F24)/HistoricalFS!F6,0) -> 0.09582019 | G14: =IFERROR((HistoricalFS!G18-HistoricalFS!G24)/HistoricalFS!G6,0) -> 0.047421359 | H14: =IFERROR((HistoricalFS!H18-HistoricalFS!H24)/HistoricalFS!H6,0) -> 0.037658444 | I14: =IFERROR((HistoricalFS!I18-HistoricalFS!I24)/HistoricalFS!I6,0) -> 0.032490734 | J14: =IFERROR((HistoricalFS!J18-HistoricalFS!J24)/HistoricalFS!J6,0) -> 0.066339319 | ... L14: =IFERROR((HistoricalFS!L18-HistoricalFS!L24)/HistoricalFS!L6,0) -> 0.087552399 | N14: =IFERROR(AVERAGE(D14:L14),0) -> 0.076208916 | O14: =IFERROR(MEDIAN(D14:L14),0) -> 0.087552399
B15: EBT Margin | C15: =IFERROR(HistoricalFS!C28,0) -> 0.10717324 | D15: =IFERROR(HistoricalFS!D28,0) -> 0.10872145 | E15: =IFERROR(HistoricalFS!E28,0) -> 0.11681205 | F15: =IFERROR(HistoricalFS!F28,0) -> 0.095154441 | G15: =IFERROR(HistoricalFS!G28,0) -> 0.046853027 | H15: =IFERROR(HistoricalFS!H28,0) -> 0.037000512 | I15: =IFERROR(HistoricalFS!I28,0) -> 0.031951844 | J15: =IFERROR(HistoricalFS!J28,0) -> 0.065941263 | ... L15: =IFERROR(HistoricalFS!L28,0) -> 0.087148902 | N15: =IFERROR(AVERAGE(D15:L15),0) -> 0.075640442 | O15: =IFERROR(MEDIAN(D15:L15),0) -> 0.087148902
B16: Net Profit Margin | C16: =IFERROR(HistoricalFS!C34,0) -> 0.070925003 | D16: =IFERROR(HistoricalFS!D34,0) -> 0.070295954 | E16: =IFERROR(HistoricalFS!E34,0) -> 0.075636454 | F16: =IFERROR(HistoricalFS!F34,0) -> 0.060609863 | G16: =IFERROR(HistoricalFS!G34,0) -> 0.028016125 | H16: =IFERROR(HistoricalFS!H34,0) -> 0.023758029 | I16: =IFERROR(HistoricalFS!I34,0) -> 0.022694493 | J16: =IFERROR(HistoricalFS!J34,0) -> 0.047976845 | ... L16: =IFERROR(HistoricalFS!L34,0) -> 0.053667118 | N16: =IFERROR(AVERAGE(D16:L16),0) -> 0.049565248 | O16: =IFERROR(MEDIAN(D16:L16),0) -> 0.053667118
B18: SalesExpenses%Sales | C18: =IFERROR(HistoricalFS!C16,0) -> 0.11697894 | D18: =IFERROR(HistoricalFS!D16,0) -> 0.11250202 | E18: =IFERROR(HistoricalFS!E16,0) -> 0.10909116 | F18: =IFERROR(HistoricalFS!F16,0) -> 0.12583001 | G18: =IFERROR(HistoricalFS!G16,0) -> 0.14073354 | H18: =IFERROR(HistoricalFS!H16,0) -> 0.1356477 | I18: =IFERROR(HistoricalFS!I16,0) -> 0.12452196 | J18: =IFERROR(HistoricalFS!J16,0) -> 0.11691629 | ... L18: =IFERROR(HistoricalFS!L16,0) -> 0.098916377 | N18: =IFERROR(AVERAGE(C18:K18),0) -> 0.12105429 | O18: =IFERROR(MEDIAN(C18:K18),0) -> 0.11697894
B19: Depreciation%Sales | C19: =IFERROR(HistoricalFS!C25,0) -> 0.048998941 | D19: =IFERROR(HistoricalFS!D25,0) -> 0.038244841 | E19: =IFERROR(HistoricalFS!E25,0) -> 0.034579887 | F19: =IFERROR(HistoricalFS!F25,0) -> 0.035097626 | G19: =IFERROR(HistoricalFS!G25,0) -> 0.046634946 | H19: =IFERROR(HistoricalFS!H25,0) -> 0.043115159 | I19: =IFERROR(HistoricalFS!I25,0) -> 0.031574848 | J19: =IFERROR(HistoricalFS!J25,0) -> 0.024033927 | ... L19: =IFERROR(HistoricalFS!L25,0) -> 0.036675757 | N19: =IFERROR(AVERAGE(C19:K19),0) -> 0.037703316 | O19: =IFERROR(MEDIAN(C19:K19),0) -> 0.037049674
B20: OperatingIncome%Sales | C20: =D14 -> 0.10924726 | D20: =E14 -> 0.11776683 | E20: =F14 -> 0.09582019 | F20: =G14 -> 0.047421359 | G20: =H14 -> 0.037658444 | H20: =I14 -> 0.032490734 | I20: =J14 -> 0.066339319 | J20: =K14 -> 0.091583708 | ... L20: =M14 -> 0 | N20: =IFERROR(AVERAGE(C20:K20),0) -> 0.076208916 | O20: =IFERROR(MEDIAN(C20:K20),0) -> 0.087552399
B22: Return on Capital Employed | C22: =IFERROR((HistoricalFS!C18-HistoricalFS!C24)/SUM(HistoricalFS!C47:C49),0) -> 0.20122281 | D22: =IFERROR((HistoricalFS!D18-HistoricalFS!D24)/SUM(HistoricalFS!D47:D49),0) -> 0.19803934 | E22: =IFERROR((HistoricalFS!E18-HistoricalFS!E24)/SUM(HistoricalFS!E47:E49),0) -> 0.22021687 | F22: =IFERROR((HistoricalFS!F18-HistoricalFS!F24)/SUM(HistoricalFS!F47:F49),0) -> 0.17453552 | G22: =IFERROR((HistoricalFS!G18-HistoricalFS!G24)/SUM(HistoricalFS!G47:G49),0) -> 0.072340923 | H22: =IFERROR((HistoricalFS!H18-HistoricalFS!H24)/SUM(HistoricalFS!H47:H49),0) -> 0.049962765 | I22: =IFERROR((HistoricalFS!I18-HistoricalFS!I24)/SUM(HistoricalFS!I47:I49),0) -> 0.051469718 | J22: =IFERROR((HistoricalFS!J18-HistoricalFS!J24)/SUM(HistoricalFS!J47:J49),0) -> 0.12372737 | ... L22: =IFERROR((HistoricalFS!L18-HistoricalFS!L24)/SUM(HistoricalFS!L47:L49),0) -> 0.13898402 | N22: =IFERROR(AVERAGE(C22:K22),0) -> 0.13811291 | O22: =IFERROR(MEDIAN(C22:K22),0) -> 0.15150091
B23: Retained Earnings% | C23: =IFERROR(HistoricalFS!C44,0) -> 0.7412168 | D23: =IFERROR(HistoricalFS!D44,0) -> 0.52675456 | E23: =IFERROR(HistoricalFS!E44,0) -> 0.59976808 | F23: =IFERROR(HistoricalFS!F44,0) -> 0.53686309 | G23: =IFERROR(HistoricalFS!G44,0) -> 0.14516205 | H23: =IFERROR(HistoricalFS!H44,0) -> 0.18715234 | I23: =IFERROR(HistoricalFS!I44,0) -> 0.096079018 | J23: =IFERROR(HistoricalFS!J44,0) -> 0.51814491 | ... L23: =IFERROR(HistoricalFS!L44,0) -> 0.48279392 | N23: =IFERROR(AVERAGE(C23:K23),0) -> 0.43493295 | O23: =IFERROR(MEDIAN(C23:K23),0) -> 0.52675456
B24: Return on Equity% | C24: =IFERROR((HistoricalFS!C33)/SUM(HistoricalFS!C47:C48),0) -> 0.13341063 | D24: =IFERROR((HistoricalFS!D33)/SUM(HistoricalFS!D47:D48),0) -> 0.12909203 | E24: =IFERROR((HistoricalFS!E33)/SUM(HistoricalFS!E47:E48),0) -> 0.14183706 | F24: =IFERROR((HistoricalFS!F33)/SUM(HistoricalFS!F47:F48),0) -> 0.11077442 | G24: =IFERROR((HistoricalFS!G33)/SUM(HistoricalFS!G47:G48),0) -> 0.042897618 | H24: =IFERROR((HistoricalFS!H33)/SUM(HistoricalFS!H47:H48),0) -> 0.03184535 | I24: =IFERROR((HistoricalFS!I33)/SUM(HistoricalFS!I47:I48),0) -> 0.036227602 | J24: =IFERROR((HistoricalFS!J33)/SUM(HistoricalFS!J47:J48),0) -> 0.091286314 | ... L24: =IFERROR((HistoricalFS!L33)/SUM(HistoricalFS!L47:L48),0) -> 0.085270247 | N24: =IFERROR(AVERAGE(C24:K24),0) -> 0.091383148 | O24: =IFERROR(MEDIAN(C24:K24),0) -> 0.1050773
B25: Self Sustained Growth Rate | C25: =IFERROR(C23*C24,0) -> 0.098886203 | D25: =IFERROR(D23*D24,0) -> 0.067999817 | E25: =IFERROR(E23*E24,0) -> 0.085069338 | F25: =IFERROR(F23*F24,0) -> 0.059470697 | G25: =IFERROR(G23*G24,0) -> 0.0062271062 | H25: =IFERROR(H23*H24,0) -> 0.0059599319 | I25: =IFERROR(I23*I24,0) -> 0.0034807124 | J25: =IFERROR(J23*J24,0) -> 0.047299539 | ... L25: =IFERROR(L23*L24,0) -> 0.041167956 | N25: =IFERROR(AVERAGE(C25:K25),0) -> 0.048175415 | O25: =IFERROR(MEDIAN(C25:K25),0) -> 0.059185389
B26: Interest Coverage Ratio | C26: =IFERROR((HistoricalFS!C18-HistoricalFS!C24)/HistoricalFS!C21,0) -> 176.84046 | D26: =IFERROR((HistoricalFS!D18-HistoricalFS!D24)/HistoricalFS!D21,0) -> 207.76816 | E26: =IFERROR((HistoricalFS!E18-HistoricalFS!E24)/HistoricalFS!E21,0) -> 123.34514 | F26: =IFERROR((HistoricalFS!F18-HistoricalFS!F24)/HistoricalFS!F21,0) -> 143.92845 | G26: =IFERROR((HistoricalFS!G18-HistoricalFS!G24)/HistoricalFS!G21,0) -> 83.439535 | H26: =IFERROR((HistoricalFS!H18-HistoricalFS!H24)/HistoricalFS!H21,0) -> 57.237581 | I26: =IFERROR((HistoricalFS!I18-HistoricalFS!I24)/HistoricalFS!I21,0) -> 60.292017 | J26: =IFERROR((HistoricalFS!J18-HistoricalFS!J24)/HistoricalFS!J21,0) -> 166.65812 | ... L26: =IFERROR((HistoricalFS!L18-HistoricalFS!L24)/HistoricalFS!L21,0) -> 216.98379 | N26: =IFERROR(AVERAGE(C26:K26),0) -> 138.51562 | O26: =IFERROR(MEDIAN(C26:K26),0) -> 143.92845
B28: Debtor Turnover Ratio | C28: =IFERROR(HistoricalFS!C6/HistoricalFS!C59,0) -> 43.515944 | D28: =IFERROR(HistoricalFS!D6/HistoricalFS!D59,0) -> 56.614835 | E28: =IFERROR(HistoricalFS!E6/HistoricalFS!E59,0) -> 54.462536 | F28: =IFERROR(HistoricalFS!F6/HistoricalFS!F59,0) -> 37.213983 | G28: =IFERROR(HistoricalFS!G6/HistoricalFS!G59,0) -> 38.256561 | H28: =IFERROR(HistoricalFS!H6/HistoricalFS!H59,0) -> 54.982421 | I28: =IFERROR(HistoricalFS!I6/HistoricalFS!I59,0) -> 43.415974 | J28: =IFERROR(HistoricalFS!J6/HistoricalFS!J59,0) -> 35.612558 | ... L28: =IFERROR(HistoricalFS!L6/HistoricalFS!L59,0) -> 23.382265 | N28: =IFERROR(AVERAGE(C28:K28),0) -> 43.881669 | O28: =IFERROR(MEDIAN(C28:K28),0) -> 43.415974
B29: Creditor Turnover Ratio | C29: =IFERROR(HistoricalFS!C6/HistoricalFS!C50,0) -> 4.8481303 | D29: =IFERROR(HistoricalFS!D6/HistoricalFS!D50,0) -> 4.7275341 | E29: =IFERROR(HistoricalFS!E6/HistoricalFS!E50,0) -> 4.5428331 | F29: =IFERROR(HistoricalFS!F6/HistoricalFS!F50,0) -> 5.1485613 | G29: =IFERROR(HistoricalFS!G6/HistoricalFS!G50,0) -> 5.3924993 | H29: =IFERROR(HistoricalFS!H6/HistoricalFS!H50,0) -> 3.8382075 | I29: =IFERROR(HistoricalFS!I6/HistoricalFS!I50,0) -> 4.6744 | J29: =IFERROR(HistoricalFS!J6/HistoricalFS!J50,0) -> 5.4536443 | ... L29: =IFERROR(HistoricalFS!L6/HistoricalFS!L50,0) -> 4.2899706 | N29: =IFERROR(AVERAGE(C29:K29),0) -> 4.8251674 | O29: =IFERROR(MEDIAN(C29:K29),0) -> 4.8006971
B30: Inventory Turnover | C30: =IFERROR(HistoricalFS!C6/HistoricalFS!C60,0) -> 18.383771 | D30: =IFERROR(HistoricalFS!D6/HistoricalFS!D60,0) -> 20.861292 | E30: =IFERROR(HistoricalFS!E6/HistoricalFS!E60,0) -> 25.254541 | F30: =IFERROR(HistoricalFS!F6/HistoricalFS!F60,0) -> 25.903961 | G30: =IFERROR(HistoricalFS!G6/HistoricalFS!G60,0) -> 23.541492 | H30: =IFERROR(HistoricalFS!H6/HistoricalFS!H60,0) -> 23.080354 | I30: =IFERROR(HistoricalFS!I6/HistoricalFS!I60,0) -> 25.006313 | J30: =IFERROR(HistoricalFS!J6/HistoricalFS!J60,0) -> 27.447485 | ... L30: =IFERROR(HistoricalFS!L6/HistoricalFS!L60,0) -> 22.11899 | N30: =IFERROR(AVERAGE(C30:K30),0) -> 24.01709 | O30: =IFERROR(MEDIAN(C30:K30),0) -> 25.006313
B31: Fixed Asset Turnover | C31: =IFERROR(HistoricalFS!C6/HistoricalFS!C53,0) -> 4.5962361 | D31: =IFERROR(HistoricalFS!D6/HistoricalFS!D53,0) -> 5.1150578 | E31: =IFERROR(HistoricalFS!E6/HistoricalFS!E53,0) -> 5.9609076 | F31: =IFERROR(HistoricalFS!F6/HistoricalFS!F53,0) -> 5.5753597 | G31: =IFERROR(HistoricalFS!G6/HistoricalFS!G53,0) -> 4.8055182 | H31: =IFERROR(HistoricalFS!H6/HistoricalFS!H53,0) -> 4.6950036 | I31: =IFERROR(HistoricalFS!I6/HistoricalFS!I53,0) -> 6.4252939 | J31: =IFERROR(HistoricalFS!J6/HistoricalFS!J53,0) -> 6.5938678 | ... L31: =IFERROR(HistoricalFS!L6/HistoricalFS!L53,0) -> 4.6361577 | N31: =IFERROR(AVERAGE(C31:K31),0) -> 5.4286879 | O31: =IFERROR(MEDIAN(C31:K31),0) -> 5.1150578
B32: Capital Turnover Ratio | C32: =IFERROR(HistoricalFS!C6/SUM(HistoricalFS!C47:C48),0) -> 1.8810099 | D32: =IFERROR(HistoricalFS!D6/SUM(HistoricalFS!D47:D48),0) -> 1.8364077 | E32: =IFERROR(HistoricalFS!E6/SUM(HistoricalFS!E47:E48),0) -> 1.8752473 | F32: =IFERROR(HistoricalFS!F6/SUM(HistoricalFS!F47:F48),0) -> 1.8276632 | G32: =IFERROR(HistoricalFS!G6/SUM(HistoricalFS!G47:G48),0) -> 1.531176 | H32: =IFERROR(HistoricalFS!H6/SUM(HistoricalFS!H47:H48),0) -> 1.3404037 | I32: =IFERROR(HistoricalFS!I6/SUM(HistoricalFS!I47:I48),0) -> 1.5963169 | J32: =IFERROR(HistoricalFS!J6/SUM(HistoricalFS!J47:J48),0) -> 1.9027161 | ... L32: =IFERROR(HistoricalFS!L6/SUM(HistoricalFS!L47:L48),0) -> 1.5888732 | N32: =IFERROR(AVERAGE(C32:K32),0) -> 1.7163851 | O32: =IFERROR(MEDIAN(C32:K32),0) -> 1.8276632
B34: (in days)
B35: Debtor Days | C35: =365/C28 -> 8.3877303 | D35: =365/D28 -> 6.4470735 | E35: =365/E28 -> 6.7018547 | F35: =365/F28 -> 9.8081412 | G35: =365/G28 -> 9.5408472 | H35: =365/H28 -> 6.6384855 | I35: =365/I28 -> 8.4070438 | J35: =365/J28 -> 10.249193 | ... L35: =365/L28 -> 15.610121 | N35: =IFERROR(AVERAGE(C35:K35),0) -> 8.6675443 | O35: =IFERROR(MEDIAN(C35:K35),0) -> 8.4070438
B36: Payable Days | C36: =365/C29 -> 75.286756 | D36: =365/D29 -> 77.20727 | E36: =365/E29 -> 80.346338 | F36: =365/F29 -> 70.893591 | G36: =365/G29 -> 67.686611 | H36: =365/H29 -> 95.096473 | I36: =365/I29 -> 78.084888 | J36: =365/J29 -> 66.927724 | ... L36: =365/L29 -> 85.082168 | N36: =IFERROR(AVERAGE(C36:K36),0) -> 76.395586 | O36: =IFERROR(MEDIAN(C36:K36),0) -> 76.030624
B37: Inventory Days | C37: =365/C30 -> 19.854469 | D37: =365/D30 -> 17.496519 | E37: =365/E30 -> 14.452846 | F37: =365/F30 -> 14.090509 | G37: =365/G30 -> 15.50454 | H37: =365/H30 -> 15.814315 | I37: =365/I30 -> 14.596314 | J37: =365/J30 -> 13.298122 | ... L37: =365/L30 -> 16.501658 | N37: =IFERROR(AVERAGE(C37:K37),0) -> 15.421229 | O37: =IFERROR(MEDIAN(C37:K37),0) -> 14.596314
B38: Cash Conversion Cycle | C38: =SUM(C35,C37)/C36 -> 0.37512838 | D38: =SUM(D35,D37)/D36 -> 0.31012096 | E38: =SUM(E35,E37)/E36 -> 0.26329391 | F38: =SUM(F35,F37)/F36 -> 0.33710594 | G38: =SUM(G35,G37)/G36 -> 0.37001981 | H38: =SUM(H35,H37)/H36 -> 0.23610551 | I38: =SUM(I35,I37)/I36 -> 0.29459424 | J38: =SUM(J35,J37)/J36 -> 0.35183201 | ... L38: =SUM(L35,L37)/L36 -> 0.37742079 | N38: =IFERROR(AVERAGE(C38:K38),0) -> 0.319304 | O38: =IFERROR(MEDIAN(C38:K38),0) -> 0.33553529
B40: CFO/Sales | C40: =IFERROR(HistoricalFS!C78/HistoricalFS!C6,0) -> 0.12493705 | D40: =IFERROR(HistoricalFS!D78/HistoricalFS!D6,0) -> 0.14602335 | E40: =IFERROR(HistoricalFS!E78/HistoricalFS!E6,0) -> 0.15630991 | F40: =IFERROR(HistoricalFS!F78/HistoricalFS!F6,0) -> 0.16959747 | G40: =IFERROR(HistoricalFS!G78/HistoricalFS!G6,0) -> 0.069865186 | H40: =IFERROR(HistoricalFS!H78/HistoricalFS!H6,0) -> 0.013144432 | I40: =IFERROR(HistoricalFS!I78/HistoricalFS!I6,0) -> 0.14934937 | J40: =IFERROR(HistoricalFS!J78/HistoricalFS!J6,0) -> -0.0082673237 | ... L40: =IFERROR(HistoricalFS!L78/HistoricalFS!L6,0) -> 0.1211277 | N40: =IFERROR(AVERAGE(C40:K40),0) -> 0.098757327 | O40: =IFERROR(MEDIAN(C40:K40),0) -> 0.12493705
B41: CFO/Total Assets | C41: =IFERROR(HistoricalFS!C78/HistoricalFS!C64,0) -> 0.1684006 | D41: =IFERROR(HistoricalFS!D78/HistoricalFS!D64,0) -> 0.19133765 | E41: =IFERROR(HistoricalFS!E78/HistoricalFS!E64,0) -> 0.20705944 | F41: =IFERROR(HistoricalFS!F78/HistoricalFS!F64,0) -> 0.22818972 | G41: =IFERROR(HistoricalFS!G78/HistoricalFS!G64,0) -> 0.083077025 | H41: =IFERROR(HistoricalFS!H78/HistoricalFS!H64,0) -> 0.01295952 | I41: =IFERROR(HistoricalFS!I78/HistoricalFS!I64,0) -> 0.176705 | J41: =IFERROR(HistoricalFS!J78/HistoricalFS!J64,0) -> -0.011489783 | ... L41: =IFERROR(HistoricalFS!L78/HistoricalFS!L64,0) -> 0.1403488 | N41: =IFERROR(AVERAGE(C41:K41),0) -> 0.12663586 | O41: =IFERROR(MEDIAN(C41:K41),0) -> 0.1684006
B42: CFO/Total Debt | C42: =IFERROR(HistoricalFS!C78/HistoricalFS!C49,0) -> 31.160676 | D42: =IFERROR(HistoricalFS!D78/HistoricalFS!D49,0) -> 20.558313 | E42: =IFERROR(HistoricalFS!E78/HistoricalFS!E49,0) -> 103.26987 | F42: =IFERROR(HistoricalFS!F78/HistoricalFS!F49,0) -> 91.4599 | G42: =IFERROR(HistoricalFS!G78/HistoricalFS!G49,0) -> 28.712656 | H42: =IFERROR(HistoricalFS!H78/HistoricalFS!H49,0) -> 1.7101128 | I42: =IFERROR(HistoricalFS!I78/HistoricalFS!I49,0) -> 31.003525 | J42: =IFERROR(HistoricalFS!J78/HistoricalFS!J49,0) -> -0.77928325 | ... L42: =IFERROR(HistoricalFS!L78/HistoricalFS!L49,0) -> 212.89655 | N42: =IFERROR(AVERAGE(C42:K42),0) -> 43.139927 | O42: =IFERROR(MEDIAN(C42:K42),0) -> 31.003525

Sheet Growth Assumptions
B2: ="Revenue Projections & Growth Assumptions - "&'Data Sheet'!B1 -> Revenue Projections & Growth Assumptions - MARUTI SUZUKI INDIA LTD
B3: Years | C3: 2026 | D3: =C3+1 -> 2027 | E3: =D3+1 -> 2028 | F3: =E3+1 -> 2029 | G3: =F3+1 -> 2030
B5: Revenue Growth % | C5: {=CHOOSE(D7,C8:G8,C9:G9,C10:G10)} -> 0.13 | D5: 0.11 | E5: 0.09 | F5: 0.13 | G5: 0.16
B6: Revenue (in Crores) | C6: =HistoricalFS!L6*(1+'Growth Assumptions'!C5) -> 172791.69 | D6: =C6*(1+D5) -> 191798.78 | E6: =D6*(1+E5) -> 209060.67 | F6: =E6*(1+F5) -> 236238.55 | G6: =F6*(1+G5) -> 274036.72
B7: Chosen Scenario: | C7: Best Case | D7: =MATCH(C7,B8:B10,) -> 2
B8: Base Case | C8: =C18 -> 0.12 | D8: =C8-$C$19 -> 0.1 | E8: =D8-$C$19 -> 0.08 | F8: =E8+3% -> 0.11 | G8: =F8+3% -> 0.14
B9: Best Case | C9: =C8+1% -> 0.13 | D9: =D8+1% -> 0.11 | E9: =E8+1% -> 0.09 | F9: =E9+4% -> 0.13 | G9: =F9+3% -> 0.16
B10: Worst Case | C10: =C8-1% -> 0.11 | D10: =D8-1% -> 0.09 | E10: =E8-1% -> 0.07 | F10: =E10 -> 0.07 | G10: =F10+2% -> 0.09
B12: Key Assumptions & Methodololy
B14: Parameter | C14: Value | D14: Rationale
B16: Valuation Date | C16: 46093
B17: Projection Period | C17: 5 Years
B18: Revenue Growth % | C18: 0.12 | D18: Based on Average of last three Quarters
B19: Annual Growth Tapering | C19: 0.02 | D19: Based on Shortage of crude oil supplies amid war (For the next 2 years only from FY27)
B21: Terminal Growth Rate | C21: 0.045 | D21: Conservative long-term growth considering India's GDP & Automobile sector potential
B23: Risk-Free Rate | C23: 0.0663 | D23: Based on 10 year Indian Government Bond Yield
B24: Equity Risk Premium (ERP) | C24: =12%-C23 -> 0.0537 | D24: Expected return over risk-free rate on equity investors
B25: Tax Rate | C25: 0.25

Sheet FCFF
B2: ="Free Cash Flow Projections - "&'Data Sheet'!B1 -> Free Cash Flow Projections - MARUTI SUZUKI INDIA LTD
B3: Years | C3: 2026 | D3: =C3+1 -> 2027 | E3: =D3+1 -> 2028 | F3: =E3+1 -> 2029 | G3: =F3+1 -> 2030
B5: Revenue | C5: ='Growth Assumptions'!C6 -> 172791.69 | D5: ='Growth Assumptions'!D6 -> 191798.78 | E5: ='Growth Assumptions'!E6 -> 209060.67 | F5: ='Growth Assumptions'!F6 -> 236238.55 | G5: ='Growth Assumptions'!G6 -> 274036.72
B6: EBIDTA Margin % | C6: =HistoricalFS!$M$19 -> 0.12791018 | D6: =HistoricalFS!$M$19 -> 0.12791018 | E6: =HistoricalFS!$M$19 -> 0.12791018 | F6: =HistoricalFS!$M$19 -> 0.12791018 | G6: =HistoricalFS!$M$19 -> 0.12791018
B7: EBIDTA | C7: =C5*C6 -> 22101.816 | D7: =D5*D6 -> 24533.016 | E7: =E5*E6 -> 26740.987 | F7: =F5*F6 -> 30217.316 | G7: =G5*G6 -> 35052.086
B8: Less: Depreciation | C8: =C5*AVERAGE(HistoricalFS!C25:M25) -> 6487.5976 | D8: =D5*AVERAGE(HistoricalFS!D25:N25) -> 6981.5629 | E8: =E5*AVERAGE(HistoricalFS!E25:O25) -> 7567.0604 | F8: =F5*AVERAGE(HistoricalFS!F25:P25) -> 8598.4878 | G8: =G5*AVERAGE(HistoricalFS!G25:Q25) -> 10025.133
B9: EBIT | C9: =C7-C8 -> 15614.219 | D9: =D7-D8 -> 17551.453 | E9: =E7-E8 -> 19173.927 | F9: =F7-F8 -> 21618.828 | G9: =G7-G8 -> 25026.954
B10: Less: Tax | C10: =C9*'Growth Assumptions'!$C$25 -> 3903.5547 | D10: =D9*'Growth Assumptions'!$C$25 -> 4387.8633 | E10: =E9*'Growth Assumptions'!$C$25 -> 4793.4818 | F10: =F9*'Growth Assumptions'!$C$25 -> 5404.707 | G10: =G9*'Growth Assumptions'!$C$25 -> 6256.7384
B11: NOPAT | C11: =C9-C10 -> 11710.664 | D11: =D9-D10 -> 13163.59 | E11: =E9-E10 -> 14380.445 | F11: =F9-F10 -> 16214.121 | G11: =G9-G10 -> 18770.215
B12: Add: Depreciation | C12: =C8 -> 6487.5976 | D12: =D8 -> 6981.5629 | E12: =E8 -> 7567.0604 | F12: =F8 -> 8598.4878 | G12: =G8 -> 10025.133
B13: Less: Reinvestment | C13: =C11*150% -> 17565.996 | D13: =D11*150% -> 19745.385 | E13: =E11*150% -> 21570.668 | F13: =F11*150% -> 24321.182 | G13: =G11*150% -> 28155.323
B14: Free Cash Flow to Firm | C14: =C11+C12-C13 -> 632.26555 | D14: =D11+D12-D13 -> 399.76802 | E14: =E11+E12-E13 -> 376.83782 | F14: =F11+F12-F13 -> 491.42729 | G14: =G11+G12-G13 -> 640.025

Sheet WACC
B2: Weighted Average Cost of Capital
B3: All figures are in INR unless stated otherwise
B4: Peer Comps
G5: Debt/ | H5: Debt/ | I5: Levered | J5: Unlevered
B6: Name of the Comp | C6: Country | D6: Total Debt | E6: Total Equity | F6: Tax Rate 1 | G6: Equity | H6: Capital | I6: Beta 2 | J6: Beta 3
B8: Maruti Suzuki | C8: India | D8: =IFERROR('Beta - Comps Data'!G3,0) -> 99.9 | E8: =IFERROR('Beta - Comps Data'!E3,0) -> 424425.58 | F8: ='Growth Assumptions'!$C$25 -> 0.25 | G8: =D8/E8 -> 0.00023537695 | H8: =D8/(D8+E8) -> 0.00023532156 | I8: 0.41 | J8: =I8/(1+(1-F8)*G8) -> 0.40992763
B9: M & M | C9: India | D9: =IFERROR('Beta - Comps Data'!G4,0) -> 126709.33 | E9: =IFERROR('Beta - Comps Data'!E4,0) -> 393968.16 | F9: ='Growth Assumptions'!$C$25 -> 0.25 | G9: =D9/E9 -> 0.32162328 | H9: =D9/(D9+E9) -> 0.24335473 | I9: 0.9 | J9: =I9/(1+(1-F9)*G9) -> 0.72509454
B10: Hyundai Motor I | C10: South Korea | D10: =IFERROR('Beta - Comps Data'!G5,0) -> 856.56 | E10: =IFERROR('Beta - Comps Data'!E5,0) -> 164148.63 | F10: ='Growth Assumptions'!$C$25 -> 0.25 | G10: =D10/E10 -> 0.0052181977 | H10: =D10/(D10+E10) -> 0.0051911094 | I10: 0.85 | J10: =I10/(1+(1-F10)*G10) -> 0.84668637
B11: Tata Motors PVeh | C11: India | D11: =IFERROR('Beta - Comps Data'!G6,0) -> 67258 | E11: =IFERROR('Beta - Comps Data'!E6,0) -> 123524.31 | F11: ='Growth Assumptions'!$C$25 -> 0.25 | G11: =D11/E11 -> 0.54449201 | H11: =D11/(D11+E11) -> 0.35253793 | I11: 1.5 | J11: =I11/(1+(1-F11)*G11) -> 1.0650618
B12: Force Motors | C12: India | D12: =IFERROR('Beta - Comps Data'!G7,0) -> 0 | E12: =IFERROR('Beta - Comps Data'!E7,0) -> 28555.84 | F12: ='Growth Assumptions'!$C$25 -> 0.25 | G12: =D12/E12 -> 0 | H12: =D12/(D12+E12) -> 0 | I12: 1.2 | J12: =I12/(1+(1-F12)*G12) -> 1.2
E14: Average | F14: =AVERAGE(F8:F12) -> 0.25 | G14: =AVERAGE(G8:G12) -> 0.17431377 | H14: =AVERAGE(H8:H12) -> 0.12026382 | I14: =AVERAGE(I8:I12) -> 0.972 | J14: =AVERAGE(J8:J12) -> 0.84935406
E15: Median | F15: =MEDIAN(F8:F12) -> 0.25 | G15: =MEDIAN(G8:G12) -> 0.0052181977 | H15: =MEDIAN(H8:H12) -> 0.0051911094 | I15: =MEDIAN(I8:I12) -> 0.9 | J15: =MEDIAN(J8:J12) -> 0.84668637
B18: Cost of Debt | G18: Cost of Equity
B20: Pre-Tax Cost of Debt | E20: 0.07 | G20: Risk Free Rate | J20: ='Growth Assumptions'!C23 -> 0.0663
B21: Tax Rate | E21: =F12 -> 0.25 | G21: Equity Risk Premium | J21: ='Growth Assumptions'!C24 -> 0.0537
B22: Post-Tax Cost of Debt | E22: =E20*(1-E21) -> 0.0525 | G22: Levered Beta 4 | J22: =J31 -> 0.85
G23: Cost of Equity | J23: =J20+J21*J22 -> 0.111945
B26: Capital Structure | G26: Levered Beta
D28: Current | E28: Target | G28: Comps Median Unlevered Beta | J28: =J15 -> 0.84668637
B29: Total Debt | C29: =D8 -> 99.9 | D29: =C29/C31 -> 0.00023532156 | E29: =H15 -> 0.0051911094 | G29: Target Debt/Equity | J29: =E33 -> 0.0052181977
B30: Market Capitalisation | C30: =E8 -> 424425.58 | D30: =C30/C31 -> 0.99976468 | E30: =E31-E29 -> 0.99480889 | G30: Tax Rate | J30: =E21 -> 0.25
B31: Total Capital | C31: =SUM(C30,C29) -> 424525.48 | D31: =SUM(D29:D30) -> 1 | E31: =D31 -> 1 | G31: Levered Beta | J31: =J28*(1+(1-J30)*J29) -> 0.85
B33: Debt/Equity | D33: =D29/D30 -> 0.00023537695 | E33: =E29/E30 -> 0.0052181977 | G33: Weighted Average Cost of Capital
B35: Notes: | G35: Cost of Equity | J35: =J23 -> 0.111945
B36: 1. Tax Rate considered as Marginal Tax Rate for the country | G36: Equity Weight | J36: =E30 -> 0.99480889
B37: 2. Levered beta is based on 5 year monthly data
B38: 3. Unlevered Beta = Levered Beta/(1+(1-Tax Rate)*Debt/Equity) | G38: Cost of Debt | J38: =E22 -> 0.0525
B39: 4. Levered Beta = Unlevered Beta*(1+(1-Tax Rate)*Debt/Equity) | G39: Debt Weight | J39: =E29 -> 0.0051911094
G41: WACC | J41: =(J35*J36)+(J38*J39) -> 0.11163641

Sheet Common Size Statement
B2: ="Common Size Income Statement"&" "&"- "&'Data Sheet'!B1 -> Common Size Income Statement - MARUTI SUZUKI INDIA LTD
B4: Particulars | C4: =IFERROR('Data Sheet'!B16,0) -> 42460 | D4: =IFERROR('Data Sheet'!C16,0) -> 42825 | E4: =IFERROR('Data Sheet'!D16,0) -> 43190 | F4: =IFERROR('Data Sheet'!E16,0) -> 43555 | G4: =IFERROR('Data Sheet'!F16,0) -> 43921 | H4: =IFERROR('Data Sheet'!G16,0) -> 44286 | I4: =IFERROR('Data Sheet'!H16,0) -> 44651 | J4: =IFERROR('Data Sheet'!I16,0) -> 45016 | ... L4: =IFERROR('Data Sheet'!K16,0) -> 45747
B6: =IFERROR('Data Sheet'!A17,0) -> Sales | C6: =IFERROR('Data Sheet'!B17/'Data Sheet'!B17,0) -> 1 | D6: =IFERROR('Data Sheet'!C17/'Data Sheet'!C17,0) -> 1 | E6: =IFERROR('Data Sheet'!D17/'Data Sheet'!D17,0) -> 1 | F6: =IFERROR('Data Sheet'!E17/'Data Sheet'!E17,0) -> 1 | G6: =IFERROR('Data Sheet'!F17/'Data Sheet'!F17,0) -> 1 | H6: =IFERROR('Data Sheet'!G17/'Data Sheet'!G17,0) -> 1 | I6: =IFERROR('Data Sheet'!H17/'Data Sheet'!H17,0) -> 1 | J6: =IFERROR('Data Sheet'!I17/'Data Sheet'!I17,0) -> 1 | ... L6: =IFERROR('Data Sheet'!K17/'Data Sheet'!K17,0) -> 1
B7: =IFERROR('Data Sheet'!A18,0) -> Raw Material Cost | C7: =IFERROR('Data Sheet'!B18/'Data Sheet'!B17,0) -> 0.67202417 | D7: =IFERROR('Data Sheet'!C18/'Data Sheet'!C17,0) -> 0.69209811 | E7: =IFERROR('Data Sheet'!D18/'Data Sheet'!D17,0) -> 0.6884565 | F7: =IFERROR('Data Sheet'!E18/'Data Sheet'!E17,0) -> 0.68952753 | G7: =IFERROR('Data Sheet'!F18/'Data Sheet'!F17,0) -> 0.70581549 | H7: =IFERROR('Data Sheet'!G18/'Data Sheet'!G17,0) -> 0.71833258 | I7: =IFERROR('Data Sheet'!H18/'Data Sheet'!H17,0) -> 0.74875184 | J7: =IFERROR('Data Sheet'!I18/'Data Sheet'!I17,0) -> 0.73703957 | ... L7: =IFERROR('Data Sheet'!K18/'Data Sheet'!K17,0) -> 0.71098141
B8: =IFERROR('Data Sheet'!A19,0) -> Change in Inventory | C8: =IFERROR('Data Sheet'!B19/'Data Sheet'!B17,0) -> -8.3349251e-05 | D8: =IFERROR('Data Sheet'!C19/'Data Sheet'!C17,0) -> 0.0055709775 | E8: =IFERROR('Data Sheet'!D19/'Data Sheet'!D17,0) -> -0.00051121798 | F8: =IFERROR('Data Sheet'!E19/'Data Sheet'!E17,0) -> -0.0024585069 | G8: =IFERROR('Data Sheet'!F19/'Data Sheet'!F17,0) -> 0.0031549035 | H8: =IFERROR('Data Sheet'!G19/'Data Sheet'!G17,0) -> -0.00388791 | I8: =IFERROR('Data Sheet'!H19/'Data Sheet'!H17,0) -> 0.0010540044 | J8: =IFERROR('Data Sheet'!I19/'Data Sheet'!I17,0) -> 0.0034353622 | ... L8: =IFERROR('Data Sheet'!K19/'Data Sheet'!K17,0) -> 0.0080274404
B9: =IFERROR('Data Sheet'!A20,0) -> Power and Fuel | C9: =IFERROR('Data Sheet'!B20/'Data Sheet'!B17,0) -> 0.012052649 | D9: =IFERROR('Data Sheet'!C20/'Data Sheet'!C17,0) -> 0.0076169494 | E9: =IFERROR('Data Sheet'!D20/'Data Sheet'!D17,0) -> 0.0084376026 | F9: =IFERROR('Data Sheet'!E20/'Data Sheet'!E17,0) -> 0.010030383 | G9: =IFERROR('Data Sheet'!F20/'Data Sheet'!F17,0) -> 0.009245308 | H9: =IFERROR('Data Sheet'!G20/'Data Sheet'!G17,0) -> 0.00677258 | I9: =IFERROR('Data Sheet'!H20/'Data Sheet'!H17,0) -> 0.0071425499 | J9: =IFERROR('Data Sheet'!I20/'Data Sheet'!I17,0) -> 0.0067193269 | ... L9: =IFERROR('Data Sheet'!K20/'Data Sheet'!K17,0) -> 0.0068836528
B10: =IFERROR('Data Sheet'!A21,0) -> Other Mfr. Exp | C10: =IFERROR('Data Sheet'!B21/'Data Sheet'!B17,0) -> 0.007428502 | D10: =IFERROR('Data Sheet'!C21/'Data Sheet'!C17,0) -> 0.0056238525 | E10: =IFERROR('Data Sheet'!D21/'Data Sheet'!D17,0) -> 0.0057900448 | F10: =IFERROR('Data Sheet'!E21/'Data Sheet'!E17,0) -> 0.005526993 | G10: =IFERROR('Data Sheet'!F21/'Data Sheet'!F17,0) -> 0.0049973566 | H10: =IFERROR('Data Sheet'!G21/'Data Sheet'!G17,0) -> 0.0097098278 | I10: =IFERROR('Data Sheet'!H21/'Data Sheet'!H17,0) -> 0.0096513294 | J10: =IFERROR('Data Sheet'!I21/'Data Sheet'!I17,0) -> 0.0095320882 | ... L10: =IFERROR('Data Sheet'!K21/'Data Sheet'!K17,0) -> 0.013042711
B11: =IFERROR('Data Sheet'!A22,0) -> Employee Cost | C11: =IFERROR('Data Sheet'!B22/'Data Sheet'!B17,0) -> 0.034734064 | D11: =IFERROR('Data Sheet'!C22/'Data Sheet'!C17,0) -> 0.03466696 | E11: =IFERROR('Data Sheet'!D22/'Data Sheet'!D17,0) -> 0.035877979 | F11: =IFERROR('Data Sheet'!E22/'Data Sheet'!E17,0) -> 0.038167274 | G11: =IFERROR('Data Sheet'!F22/'Data Sheet'!F17,0) -> 0.045151996 | H11: =IFERROR('Data Sheet'!G22/'Data Sheet'!G17,0) -> 0.048763713 | I11: =IFERROR('Data Sheet'!H22/'Data Sheet'!H17,0) -> 0.04586674 | J11: =IFERROR('Data Sheet'!I22/'Data Sheet'!I17,0) -> 0.039419484 | ... L11: =IFERROR('Data Sheet'!K22/'Data Sheet'!K17,0) -> 0.045947696
B12: =IFERROR('Data Sheet'!A23,0) -> Selling and admin | C12: =IFERROR('Data Sheet'!B23/'Data Sheet'!B17,0) -> 0.09320009 | D12: =IFERROR('Data Sheet'!C23/'Data Sheet'!C17,0) -> 0.089759859 | E12: =IFERROR('Data Sheet'!D23/'Data Sheet'!D17,0) -> 0.084642912 | F12: =IFERROR('Data Sheet'!E23/'Data Sheet'!E17,0) -> 0.097483981 | G12: =IFERROR('Data Sheet'!F23/'Data Sheet'!F17,0) -> 0.11176712 | H12: =IFERROR('Data Sheet'!G23/'Data Sheet'!G17,0) -> 0.1126016 | I12: =IFERROR('Data Sheet'!H23/'Data Sheet'!H17,0) -> 0.10323922 | J12: =IFERROR('Data Sheet'!I23/'Data Sheet'!I17,0) -> 0.099471555 | ... L12: =IFERROR('Data Sheet'!K23/'Data Sheet'!K17,0) -> 0.075358537
B13: =IFERROR('Data Sheet'!A24,0) -> Other Expenses | C13: =IFERROR('Data Sheet'!B24/'Data Sheet'!B17,0) -> 0.023778847 | D13: =IFERROR('Data Sheet'!C24/'Data Sheet'!C17,0) -> 0.022742161 | E13: =IFERROR('Data Sheet'!D24/'Data Sheet'!D17,0) -> 0.024448248 | F13: =IFERROR('Data Sheet'!E24/'Data Sheet'!E17,0) -> 0.028346027 | G13: =IFERROR('Data Sheet'!F24/'Data Sheet'!F17,0) -> 0.028966429 | H13: =IFERROR('Data Sheet'!G24/'Data Sheet'!G17,0) -> 0.023046098 | I13: =IFERROR('Data Sheet'!H24/'Data Sheet'!H17,0) -> 0.021282738 | J13: =IFERROR('Data Sheet'!I24/'Data Sheet'!I17,0) -> 0.017444734 | ... L13: =IFERROR('Data Sheet'!K24/'Data Sheet'!K17,0) -> 0.02355784
B14: =IFERROR('Data Sheet'!A25,0) -> Other Income | C14: =IFERROR('Data Sheet'!B25/'Data Sheet'!B17,0) -> 0.025423258 | D14: =IFERROR('Data Sheet'!C25/'Data Sheet'!C17,0) -> 0.035238305 | E14: =IFERROR('Data Sheet'!D25/'Data Sheet'!D17,0) -> 0.02699682 | F14: =IFERROR('Data Sheet'!E25/'Data Sheet'!E17,0) -> 0.030954414 | G14: =IFERROR('Data Sheet'!F25/'Data Sheet'!F17,0) -> 0.045075337 | H14: =IFERROR('Data Sheet'!G25/'Data Sheet'!G17,0) -> 0.043288524 | I14: =IFERROR('Data Sheet'!H25/'Data Sheet'!H17,0) -> 0.021066503 | J14: =IFERROR('Data Sheet'!I25/'Data Sheet'!I17,0) -> 0.019618733 | ... L14: =IFERROR('Data Sheet'!K25/'Data Sheet'!K17,0) -> 0.033998417
B15: =IFERROR('Data Sheet'!A26,0) -> Depreciation | C15: =IFERROR('Data Sheet'!B26/'Data Sheet'!B17,0) -> 0.048998941 | D15: =IFERROR('Data Sheet'!C26/'Data Sheet'!C17,0) -> 0.038244841 | E15: =IFERROR('Data Sheet'!D26/'Data Sheet'!D17,0) -> 0.034579887 | F15: =IFERROR('Data Sheet'!E26/'Data Sheet'!E17,0) -> 0.035097626 | G15: =IFERROR('Data Sheet'!F26/'Data Sheet'!F17,0) -> 0.046634946 | H15: =IFERROR('Data Sheet'!G26/'Data Sheet'!G17,0) -> 0.043115159 | I15: =IFERROR('Data Sheet'!H26/'Data Sheet'!H17,0) -> 0.031574848 | J15: =IFERROR('Data Sheet'!I26/'Data Sheet'!I17,0) -> 0.024033927 | ... L15: =IFERROR('Data Sheet'!K26/'Data Sheet'!K17,0) -> 0.036675757
B16: =IFERROR('Data Sheet'!A27,0) -> Interest | C16: =IFERROR('Data Sheet'!B27/'Data Sheet'!B17,0) -> 0.0014186737 | D16: =IFERROR('Data Sheet'!C27/'Data Sheet'!C17,0) -> 0.0013130646 | E16: =IFERROR('Data Sheet'!D27/'Data Sheet'!D17,0) -> 0.004332823 | F16: =IFERROR('Data Sheet'!E27/'Data Sheet'!E17,0) -> 0.00088185573 | G16: =IFERROR('Data Sheet'!F27/'Data Sheet'!F17,0) -> 0.0017737246 | H16: =IFERROR('Data Sheet'!G27/'Data Sheet'!G17,0) -> 0.0014465981 | I16: =IFERROR('Data Sheet'!H27/'Data Sheet'!H17,0) -> 0.0014332649 | J16: =IFERROR('Data Sheet'!I27/'Data Sheet'!I17,0) -> 0.0015905242 | ... L16: =IFERROR('Data Sheet'!K27/'Data Sheet'!K17,0) -> 0.0012700032
B17: =IFERROR('Data Sheet'!A28,0) -> Profit before tax | C17: =IFERROR('Data Sheet'!B28/'Data Sheet'!B17,0) -> 0.13170397 | D17: =IFERROR('Data Sheet'!C28/'Data Sheet'!C17,0) -> 0.14874348 | E17: =IFERROR('Data Sheet'!D28/'Data Sheet'!D17,0) -> 0.13991961 | F17: =IFERROR('Data Sheet'!E28/'Data Sheet'!E17,0) -> 0.12343424 | G17: =IFERROR('Data Sheet'!F28/'Data Sheet'!F17,0) -> 0.093877875 | H17: =IFERROR('Data Sheet'!G28/'Data Sheet'!G17,0) -> 0.07561246 | I17: =IFERROR('Data Sheet'!H28/'Data Sheet'!H17,0) -> 0.053177976 | J17: =IFERROR('Data Sheet'!I28/'Data Sheet'!I17,0) -> 0.087802891 | ... L17: =IFERROR('Data Sheet'!K28/'Data Sheet'!K17,0) -> 0.12830825
B18: =IFERROR('Data Sheet'!A29,0) -> Tax | C18: =IFERROR('Data Sheet'!B29/'Data Sheet'!B17,0) -> 0.036248242 | D18: =IFERROR('Data Sheet'!C29/'Data Sheet'!C17,0) -> 0.038425498 | E18: =IFERROR('Data Sheet'!D29/'Data Sheet'!D17,0) -> 0.041175601 | F18: =IFERROR('Data Sheet'!E29/'Data Sheet'!E17,0) -> 0.034544578 | G18: =IFERROR('Data Sheet'!F29/'Data Sheet'!F17,0) -> 0.018836902 | H18: =IFERROR('Data Sheet'!G29/'Data Sheet'!G17,0) -> 0.013242483 | I18: =IFERROR('Data Sheet'!H29/'Data Sheet'!H17,0) -> 0.0092573514 | J18: =IFERROR('Data Sheet'!I29/'Data Sheet'!I17,0) -> 0.017964418 | ... L18: =IFERROR('Data Sheet'!K29/'Data Sheet'!K17,0) -> 0.033481784
B19: =IFERROR('Data Sheet'!A30,0) -> Net profit | C19: =IFERROR('Data Sheet'!B30/'Data Sheet'!B17,0) -> 0.095455729 | D19: =IFERROR('Data Sheet'!C30/'Data Sheet'!C17,0) -> 0.11030183 | E19: =IFERROR('Data Sheet'!D30/'Data Sheet'!D17,0) -> 0.098735237 | F19: =IFERROR('Data Sheet'!E30/'Data Sheet'!E17,0) -> 0.088872235 | G19: =IFERROR('Data Sheet'!F30/'Data Sheet'!F17,0) -> 0.075019826 | H19: =IFERROR('Data Sheet'!G30/'Data Sheet'!G17,0) -> 0.062369977 | I19: =IFERROR('Data Sheet'!H30/'Data Sheet'!H17,0) -> 0.043920625 | J19: =IFERROR('Data Sheet'!I30/'Data Sheet'!I17,0) -> 0.069838472 | ... L19: =IFERROR('Data Sheet'!K30/'Data Sheet'!K17,0) -> 0.09482647
B20: =IFERROR('Data Sheet'!A31,0) -> Dividend Amount | C20: =IFERROR('Data Sheet'!B31/'Data Sheet'!B17,0) -> 0.0183542 | D20: =IFERROR('Data Sheet'!C31/'Data Sheet'!C17,0) -> 0.033267239 | E20: =IFERROR('Data Sheet'!D31/'Data Sheet'!D17,0) -> 0.030272123 | F20: =IFERROR('Data Sheet'!E31/'Data Sheet'!E17,0) -> 0.028070665 | G20: =IFERROR('Data Sheet'!F31/'Data Sheet'!F17,0) -> 0.023949247 | H20: =IFERROR('Data Sheet'!G31/'Data Sheet'!G17,0) -> 0.019311658 | I20: =IFERROR('Data Sheet'!H31/'Data Sheet'!H17,0) -> 0.020514028 | J20: =IFERROR('Data Sheet'!I31/'Data Sheet'!I17,0) -> 0.023117887 | ... L20: =IFERROR('Data Sheet'!K31/'Data Sheet'!K17,0) -> 0.02775696
B22: ="Common Size Balance Sheet"&" "&"- "&'Data Sheet'!B1 -> Common Size Balance Sheet - MARUTI SUZUKI INDIA LTD
B24: Particulars | C24: =IFERROR('Data Sheet'!B56,0) -> 42460 | D24: =IFERROR('Data Sheet'!C56,0) -> 42825 | E24: =IFERROR('Data Sheet'!D56,0) -> 43190 | F24: =IFERROR('Data Sheet'!E56,0) -> 43555 | G24: =IFERROR('Data Sheet'!F56,0) -> 43921 | H24: =IFERROR('Data Sheet'!G56,0) -> 44286 | I24: =IFERROR('Data Sheet'!H56,0) -> 44651 | J24: =IFERROR('Data Sheet'!I56,0) -> 45016 | ... L24: =IFERROR('Data Sheet'!K56,0) -> 45747
B26: Total Liabilities | C26: =IFERROR('Data Sheet'!B61/'Data Sheet'!B61,0) -> 1 | D26: =IFERROR('Data Sheet'!C61/'Data Sheet'!C61,0) -> 1 | E26: =IFERROR('Data Sheet'!D61/'Data Sheet'!D61,0) -> 1 | F26: =IFERROR('Data Sheet'!E61/'Data Sheet'!E61,0) -> 1 | G26: =IFERROR('Data Sheet'!F61/'Data Sheet'!F61,0) -> 1 | H26: =IFERROR('Data Sheet'!G61/'Data Sheet'!G61,0) -> 1 | I26: =IFERROR('Data Sheet'!H61/'Data Sheet'!H61,0) -> 1 | J26: =IFERROR('Data Sheet'!I61/'Data Sheet'!I61,0) -> 1 | ... L26: =IFERROR('Data Sheet'!K61/'Data Sheet'!K61,0) -> 1
B27: =IFERROR('Data Sheet'!A57,0) -> Equity Share Capital | C27: =IFERROR('Data Sheet'!B57/'Data Sheet'!B61,0) -> 0.0035341892 | D27: =IFERROR('Data Sheet'!C57/'Data Sheet'!C61,0) -> 0.0029060536 | E27: =IFERROR('Data Sheet'!D57/'Data Sheet'!D61,0) -> 0.0025062906 | F27: =IFERROR('Data Sheet'!E57/'Data Sheet'!E61,0) -> 0.0023605294 | G27: =IFERROR('Data Sheet'!F57/'Data Sheet'!F61,0) -> 0.0023731802 | H27: =IFERROR('Data Sheet'!G57/'Data Sheet'!G61,0) -> 0.0021155541 | I27: =IFERROR('Data Sheet'!H57/'Data Sheet'!H61,0) -> 0.0020226239 | J27: =IFERROR('Data Sheet'!I57/'Data Sheet'!I61,0) -> 0.0017849354 | ... L27: =IFERROR('Data Sheet'!K57/'Data Sheet'!K61,0) -> 0.001191169
B28: =IFERROR('Data Sheet'!A58,0) -> Reserves | C28: =IFERROR('Data Sheet'!B58/'Data Sheet'!B61,) -> 0.71304022 | D28: =IFERROR('Data Sheet'!C58/'Data Sheet'!C61,) -> 0.71061864 | E28: =IFERROR('Data Sheet'!D58/'Data Sheet'!D61,) -> 0.70389255 | F28: =IFERROR('Data Sheet'!E58/'Data Sheet'!E61,) -> 0.73381357 | G28: =IFERROR('Data Sheet'!F58/'Data Sheet'!F61,) -> 0.77422255 | H28: =IFERROR('Data Sheet'!G58/'Data Sheet'!G61,) -> 0.73343318 | I28: =IFERROR('Data Sheet'!H58/'Data Sheet'!H61,) -> 0.73916188 | J28: =IFERROR('Data Sheet'!I58/'Data Sheet'!I61,) -> 0.72863545 | ... L28: =IFERROR('Data Sheet'!K58/'Data Sheet'!K61,) -> 0.72805809
B29: =IFERROR('Data Sheet'!A59,0) -> Borrowings | C29: =IFERROR('Data Sheet'!B59/'Data Sheet'!B61,0) -> 0.0054042668 | D29: =IFERROR('Data Sheet'!C59/'Data Sheet'!C61,0) -> 0.0093070698 | E29: =IFERROR('Data Sheet'!D59/'Data Sheet'!D61,0) -> 0.0020050325 | F29: =IFERROR('Data Sheet'!E59/'Data Sheet'!E61,0) -> 0.0024949702 | G29: =IFERROR('Data Sheet'!F59/'Data Sheet'!F61,0) -> 0.0028933939 | H29: =IFERROR('Data Sheet'!G59/'Data Sheet'!G61,0) -> 0.0075781669 | I29: =IFERROR('Data Sheet'!H59/'Data Sheet'!H61,0) -> 0.0056995131 | J29: =IFERROR('Data Sheet'!I59/'Data Sheet'!I61,0) -> 0.014744039 | ... L29: =IFERROR('Data Sheet'!K59/'Data Sheet'!K61,0) -> 0.00065923474
B30: =IFERROR('Data Sheet'!A60,0) -> Other Liabilities | C30: =IFERROR('Data Sheet'!B60/'Data Sheet'!B61,0) -> 0.27802132 | D30: =IFERROR('Data Sheet'!C60/'Data Sheet'!C61,0) -> 0.27716823 | E30: =IFERROR('Data Sheet'!D60/'Data Sheet'!D61,0) -> 0.29159613 | F30: =IFERROR('Data Sheet'!E60/'Data Sheet'!E61,0) -> 0.26133093 | G30: =IFERROR('Data Sheet'!F60/'Data Sheet'!F61,0) -> 0.22051088 | H30: =IFERROR('Data Sheet'!G60/'Data Sheet'!G61,0) -> 0.2568731 | I30: =IFERROR('Data Sheet'!H60/'Data Sheet'!H61,0) -> 0.25311598 | J30: =IFERROR('Data Sheet'!I60/'Data Sheet'!I61,0) -> 0.25483558 | ... L30: =IFERROR('Data Sheet'!K60/'Data Sheet'!K61,0) -> 0.2700915
B32: Total Assets | C32: =IFERROR('Data Sheet'!B74/'Data Sheet'!B74,0) -> 1 | D32: =IFERROR('Data Sheet'!C74/'Data Sheet'!C74,0) -> 1 | E32: =IFERROR('Data Sheet'!D74/'Data Sheet'!D74,0) -> 1 | F32: =IFERROR('Data Sheet'!E74/'Data Sheet'!E74,0) -> 1 | G32: =IFERROR('Data Sheet'!F74/'Data Sheet'!F74,0) -> 1 | H32: =IFERROR('Data Sheet'!G74/'Data Sheet'!G74,0) -> 1 | I32: =IFERROR('Data Sheet'!H74/'Data Sheet'!H74,0) -> 1 | J32: =IFERROR('Data Sheet'!I74/'Data Sheet'!I74,0) -> 1 | ... L32: =IFERROR('Data Sheet'!K74/'Data Sheet'!K74,0) -> 1
B33: =IFERROR('Data Sheet'!A62,0) -> Net Block | C33: =IFERROR('Data Sheet'!B62/'Data Sheet'!B74,0) -> 0.26527665 | D33: =IFERROR('Data Sheet'!C62/'Data Sheet'!C74,0) -> 0.23579503 | E33: =IFERROR('Data Sheet'!D62/'Data Sheet'!D74,0) -> 0.20614646 | F33: =IFERROR('Data Sheet'!E62/'Data Sheet'!E74,0) -> 0.22119042 | G33: =IFERROR('Data Sheet'!F62/'Data Sheet'!F74,0) -> 0.22868248 | H33: =IFERROR('Data Sheet'!G62/'Data Sheet'!G74,0) -> 0.19032762 | I33: =IFERROR('Data Sheet'!H62/'Data Sheet'!H74,0) -> 0.16510277 | J33: =IFERROR('Data Sheet'!I62/'Data Sheet'!I74,0) -> 0.19333922 | ... L33: =IFERROR('Data Sheet'!K62/'Data Sheet'!K74,0) -> 0.2259445
B34: =IFERROR('Data Sheet'!A63,0) -> Capital Work in Progress | C34: =IFERROR('Data Sheet'!B63/'Data Sheet'!B74,0) -> 0.021318084 | D34: =IFERROR('Data Sheet'!C63/'Data Sheet'!C74,0) -> 0.022184116 | E34: =IFERROR('Data Sheet'!D63/'Data Sheet'!D74,0) -> 0.032827801 | F34: =IFERROR('Data Sheet'!E63/'Data Sheet'!E74,0) -> 0.023024162 | G34: =IFERROR('Data Sheet'!F63/'Data Sheet'!F74,0) -> 0.020555337 | H34: =IFERROR('Data Sheet'!G63/'Data Sheet'!G74,0) -> 0.019006477 | I34: =IFERROR('Data Sheet'!H63/'Data Sheet'!H74,0) -> 0.035267131 | J34: =IFERROR('Data Sheet'!I63/'Data Sheet'!I74,0) -> 0.031489839 | ... L34: =IFERROR('Data Sheet'!K63/'Data Sheet'!K74,0) -> 0.054316776
B35: =IFERROR('Data Sheet'!A64,0) -> Investments | C35: =IFERROR('Data Sheet'!B64/'Data Sheet'!B74,0) -> 0.43774798 | D35: =IFERROR('Data Sheet'!C64/'Data Sheet'!C74,0) -> 0.51639407 | E35: =IFERROR('Data Sheet'!D64/'Data Sheet'!D74,0) -> 0.55618495 | F35: =IFERROR('Data Sheet'!E64/'Data Sheet'!E74,0) -> 0.53736322 | G35: =IFERROR('Data Sheet'!F64/'Data Sheet'!F74,0) -> 0.54450146 | H35: =IFERROR('Data Sheet'!G64/'Data Sheet'!G74,0) -> 0.54531625 | I35: =IFERROR('Data Sheet'!H64/'Data Sheet'!H74,0) -> 0.50483339 | J35: =IFERROR('Data Sheet'!I64/'Data Sheet'!I74,0) -> 0.53331692 | ... L35: =IFERROR('Data Sheet'!K64/'Data Sheet'!K74,0) -> 0.45394411
